Workbook

Sheet HEINEKEN
A1: DT | B1: REMESSA | C1: DATA | D1: PL | E1: Peso | F1: Frete | G1: Canal | H1: Cliente | I1: CNPJ Destinatário | J1: Origem | K1: Cidade | L1: UF | M1: Frota / Placa | N1: Tarifa OTM | O1: Margem CF | P1: Valor CF | Q1: OC | R1: Romaneio | S1: Status | T1: Monitoramento (SM) | U1: DT/Hora Chegada Coleta | V1: Saída Coleta | W1: Tempo de Permanência | X1: Agenda Descarga | Y1: DT/ Hora Chegada no Cliente | Z1: Data/Hora Descarga | AA1: Tempo de Permanência | AB1: OC Galileu / Shipsy | AC1: Motivo | AD1: Valor | AE1: Baixa Galileu / Shipsy | AF1: Upload de cahotos
A2: 10064649 | C2: 45293 | D2: 26 | E2: 31625 | F2: TE01 | G2: DTB | H2: COMPAR RIO BRANCO-AC | I2: 04.928.297/0020-73 | J2: PONTA GROSSA | K2: RIO BRANCO | L2: AC | M2: AWB3J16 / MFR2D98 | N2: 35374.19 | O2: =IFERROR(P2/N2,0) -> 0.76326836 | P2: 27000 | Q2: OK | R2: 1248852 | S2: CARREGADO | T2: 4731490 | Y2: 09/01/2024 08:33 | Z2: 09/01 18:25 | AE2: OK
A3: 10070792 | C3: 45293 | D3: 26 | E3: 32553 | F3: TE02 | G3: TRF | H3: CDA CURITIBA-PR | I3: 50.221.019/0083-82 | J3: PONTA GROSSA | K3: CURITIBA | L3: PR | M3: A18000 | N3: 2336.24 | O3: =IFERROR(P3/N3,0) -> 0.64205732 | P3: 1500 | Q3: OK | R3: 1248704 | S3: CARREGADO | T3: 4730568 | Y3: 04/01/2024 6:41 | Z3: 04/01 13:30 | AE3: OK
A4: 10070793 | C4: 45293 | D4: - | E4: - | F4: TE02 | G4: TRF | H4: (RETORNO TE02) CDA CURITIBA-PR | I4: 50.221.019/0083-82 | J4: CURITIBA | K4: PONTA GROSSA | L4: PR | M4: A18000 | N4: 1557.49 | O4: =IFERROR(P4/N4,0) -> 0.44944109 | P4: 700 | R4: 1249431 | S4: CARREGADO | T4: 4734222 | Y4: 05/01/2024 23:56 | Z4: 05/01 23:56 | AE4: OK
A5: 10083900 | C5: 45296.833 | D5: 26 | E5: 32647 | F5: TE01 | G5: DTB | H5: SPAL JOINVILLE-SC | I5: 61.186.888/0175-92 | J5: PONTA GROSSA | K5: JOINVILLE | L5: SC | M5: A18000 | N5: 3587.66 | O5: =IFERROR(P5/N5,0) -> 0.66895971 | P5: 2400 | Q5: OK | R5: 1250023 | S5: CARREGADO | T5: 4737234 | Y5: 09/01 08:57 | Z5: 09/01 08:57 | AE5: OK
A6: 10085050 | C6: 45294 | D6: 26 | E6: 31625 | F6: TE01 | G6: DTB | H6: CDA BLUMENAU-SC | I6: 50.221.019/0077-34 | J6: PONTA GROSSA | K6: BLUMENAU | L6: SC | M6: A54730 | N6: 4696.34 | O6: =IFERROR(P6/N6,0) -> 0.68138167 | P6: 3200 | Q6: OK | R6: 1248860 | S6: CARREGADO | T6: 4731554 | Y6: 04/01 09:18 | Z6: 04/01 09:18 | AE6: OK
A7: 10086808 | C7: 45299.667 | D7: 26 | E7: 31647 | F7: TE01 | G7: DTB | H7: SPAL ANTÔNIO CARLOS-SC | I7: 61.186.888/0176-73 | J7: PONTA GROSSA | K7: ANTONIO CARLOS | L7: SC | M7: A54920 | N7: 4445.42 | O7: =IFERROR(P7/N7,0) -> 0.6999991 | P7: 3111.79 | Q7: OK | R7: 1251657 | S7: CARREGADO | T7: 4744497 | Y7: 10/01 07:54 | Z7: 10/01 11:35 | AE7: OK
A8: 10086825 | C8: 45296.583 | D8: 26 | E8: 31647 | F8: TE01 | G8: DTB | H8: SPAL ANTÔNIO CARLOS-SC | I8: 61.186.888/0176-73 | J8: PONTA GROSSA | K8: ANTONIO CARLOS | L8: SC | M8: A54730 | N8: 4445.42 | O8: =IFERROR(P8/N8,0) -> 0.6999991 | P8: 3111.79 | Q8: OK | R8: 1250012 | S8: CARREGADO | T8: 4737183 | Y8: 06/01 17:31 | Z8: 09/01 10:25 | AE8: OK
A9: 10103146 | C9: 45306.875 | D9: 26 | E9: 31625 | F9: TE01 | G9: ASD | H9: ASUN GRAVATAÍ-RS | I9: 92.091.891/0001-57 | J9: PONTA GROSSA | K9: GRAVATAÍ | L9: RS | M9: A18000 | N9: 9203.69 | O9: =IFERROR(P9/N9,0) -> 0.54326037 | P9: 5000 | Q9: OK | R9: 1255065 | S9: CARREGADO | T9: 4762159 | Y9: 16/01 13:36 | Z9: 19/01 12:18 | AE9: OK
A10: 10120665 | C10: 45313.542 | D10: 26 | E10: 33069 | F10: TE01 | G10: DTB | H10: COMPAR RIO BRANCO-AC | I10: 04.928.297/0020-73 | J10: PONTA GROSSA | K10: RIO BRANCO | L10: AC | M10: AWB3J16 / MFR2D98 | N10: 32898 | O10: =IFERROR(P10/N10,0) -> 0.85111557 | P10: 28000 | Q10: OK | R10: 1259245 | S10: CARREGADO | T10: 4784522 | Y10: 30/01 10:00 | Z10: 30/01 16:00 | AE10: OK
A11: 10120977 | C11: 45311.458 | D11: 26 | E11: 32647 | F11: TE01 | G11: DTB | H11: SPAL JOINVILLE-SC | I11: 61.186.888/0175-92 | J11: PONTA GROSSA | K11: JOINVILLE | L11: SC | M11: A55160 | N11: 3587.66 | O11: =IFERROR(P11/N11,0) -> 0.66895971 | P11: 2400 | Q11: OK | R11: 1258507 | S11: CARREGADO | T11: 4782100 | Y11: 21/01 16:14 | Z11: 22/01 07:42 | AE11: OK
A12: 10123614 | C12: 45313.333 | D12: 26 | E12: 32647 | F12: TE01 | G12: DTB | H12: SPAL ANTÔNIO CARLOS -SC | I12: 61.186.888/0176-73 | J12: PONTA GROSSA | K12: ANTONIO CARLOS | L12: SC | M12: A54920 | N12: 4445.42 | O12: =IFERROR(P12/N12,0) -> 0.67485187 | P12: 3000 | Q12: OK | R12: 1259251 | S12: CARREGADO | T12: 4784537 | Y12: 24/01 15:45 | Z12: 24/01 18:41 | AE12: OK
A13: 10123615 | C13: 45313.333 | D13: 26 | E13: 32647 | F13: TE01 | G13: DTB | H13: SPAL ANTÔNIO CARLOS -SC | I13: 61.186.888/0176-73 | J13: PONTA GROSSA | K13: ANTONIO CARLOS | L13: SC | M13: A18000 | N13: 4445.42 | O13: =IFERROR(P13/N13,0) -> 0.6999991 | P13: 3111.79 | Q13: OK | R13: 1259152 | S13: CARREGADO | T13: 4784032 | Y13: 24/01 22:33 | Z13: 25/01 10:16 | AE13: OK
A14: 10141197 | C14: 45318.833 | D14: 26 | E14: 32553 | F14: TE02 | G14: DTB | H14: DBK SÃO JOSÉ DO RIO PRETO-SP | I14: 14.886.581/0001-15 | J14: PONTA GROSSA | K14: SÃO JOSÉ DO RIO PRETO | L14: SP | M14: A55160 | N14: 6085.8 | O14: =IFERROR(P14/N14,0) -> 0.73942621 | P14: 4500 | Q14: OK | R14: 1262201 | S14: CARREGADO | T14: 4802275 | Y14: 28/01 16:06 | Z14: 29/01 15:58 | AE14: OK
A15: 10141198 | C15: 45318.833 | D15: 25 | E15: 30278 | F15: TE01 | G15: ASD | H15: ASUN GRAVATAÍ-RS | I15: 92.091.891/0001-57 | J15: PONTA GROSSA | K15: GRAVATAÍ | L15: RS | M15: A18000 | N15: 9203.69 | O15: =IFERROR(P15/N15,0) -> 0.54326037 | P15: 5000 | Q15: OK | R15: 1262200 | S15: CARREGADO | T15: 4802274 | Y15: 29/01 19:33 | Z15: 06/02 08:36 | AA15: 7 dias | AB15: OK | AC15: DIÁRIA | AD15: 2450 | AE15: OK
A16: 10141199 | C16: 45318.833 | D16: - | E16: - | F16: TE02 | G16: DTB | H16: (RETORNO TE02) DBK SÃO JOSÉ DO RIO PRETO-SP | I16: 14.886.581/0001-15 | J16: SÃO JOSÉ DO RIO PRETO | K16: PONTA GROSSA | L16: PR | M16: A55160 | N16: 4057.2 | O16: =IFERROR(P16/N16,0) -> 0.73942621 | P16: 3000 | R16: 1263554 | S16: CARREGADO | T16: 4807467 | Y16: 30/01 22:23 | Z16: 31/01 00:08 | AE16: OK
A17: 10152226 | C17: 45323.417 | D17: 26 | E17: 33139 | F17: TE02 | G17: TRF | H17: HNK SÃO JOSÉ-SC | I17: 50.221.019/0076-53 | J17: PONTA GROSSA | K17: SÃO JOSÉ | L17: SC | M17: A55160 | N17: 5305 | O17: =IFERROR(P17/N17,0) -> 0.56550424 | P17: 3000 | Q17: OK | R17: 1265449 | S17: CARREGADO | T17: 4818839 | Y17: 45327.36 | Z17: 45327.478 | AE17: OK
A18: 10154687 | C18: 45323.833 | D18: 26 | E18: 32553 | F18: TE02 | G18: TRF | H18: CDA CURITIBA-PR | I18: 50.221.019/0083-82 | J18: PONTA GROSSA | K18: CURITIBA | L18: PR CAP. | M18: A54730 | N18: 2336.24 | O18: =IFERROR(P18/N18,0) -> 0.64205732 | P18: 1500 | Q18: OK | R18: 1265383 | S18: CARREGADO | T18: 4818348 | Y18: 45323.357 | Z18: 45323.453 | AE18: OK
A19: 10154698 | C19: 45324.375 | D19: - | E19: - | F19: TE02 | G19: TRF | H19: (RETORNO TE02) CDA CURITIBA-PR | I19: 50.221.019/0083-82 | J19: CURITIBA | K19: PONTA GROSSA | L19: TE02 PR | M19: A54730 | N19: 1557.5 | O19: =IFERROR(P19/N19,0) -> 0.4494382 | P19: 700 | R19: 1265532 | S19: CARREGADO | T19: 4819599 | Y19: 45324.05 | Z19: 45324.113 | AE19: OK
A20: 10166462 | C20: 45327.625 | D20: 26 | E20: 32249 | F20: TE01 | G20: DTB | H20: LAGO AZUL MARÍLIA-SP | I20: 58.844.424/0002-01 | J20: PONTA GROSSA | K20: MARÍLIA | L20: SP INT. | M20: A56430 | N20: 4325 | O20: =IFERROR(P20/N20,0) -> 0.69364162 | P20: 3000 | Q20: OK | R20: 1267501 | S20: CARREGADO | T20: 4828032 | Y20: 45327.881 | Z20: 45328.514 | AE20: OK
A21: 10170659 | C21: 45327.208 | D21: 26 | E21: 32553 | F21: TE02 | G21: TRF | H21: CDA CURITIBA-PR | I21: 50.221.019/0083-82 | J21: PONTA GROSSA | K21: CURITIBA | L21: PR CAP. | M21: A54730 | N21: 2336.24 | O21: =IFERROR(P21/N21,0) -> 0.64205732 | P21: 1500 | Q21: OK | R21: 1267506 | S21: CARREGADO | T21: 4828109 | Y21: 45327.673 | Z21: 45327.758 | AE21: OK
A22: 10170660 | C22: 45329.625 | D22: - | E22: - | F22: TE02 | G22: TRF | H22: (RETORNO TE02) CDA CURITIBA-PR | I22: 50.221.019/0083-82 | J22: CURITIBA | K22: PONTA GROSSA | L22: TE02 PR | M22: A54730 | N22: 1557.5 | O22: =IFERROR(P22/N22,0) -> 0.4494382 | P22: 700 | R22: 1268167 | S22: CARREGADO | T22: 4831936 | Y22: 45329.018 | Z22: 45329.062 | AE22: OK
A23: 10171561 | C23: 45325.667 | D23: 26 | E23: 32553 | F23: TE02 | G23: TRF | H23: HNK SÃO JOSÉ-SC | I23: 05.254.957/0038-70 | J23: PONTA GROSSA | K23: SÃO JOSÉ | L23: SC | M23: A55650 | N23: 4717.8 | O23: =IFERROR(P23/N23,0) -> 0.63588961 | P23: 3000 | Q23: OK | R23: 1266780 | S23: CARREGADO | T23: 4826244 | Y23: 45327.456 | Z23: 45327.593 | AE23: OK
A24: 10171562 | C24: 45325.625 | D24: 26 | E24: 32553 | F24: TE02 | G24: TRF | H24: HNK SÃO JOSÉ-SC | I24: 50.221.019/0076-53 | J24: PONTA GROSSA | K24: SÃO JOSÉ | L24: SC | M24: A57390 | N24: 4717.8 | O24: =IFERROR(P24/N24,0) -> 0.63588961 | P24: 3000 | Q24: OK | R24: 1266592 | S24: CARREGADO | T24: 4825303 | Y24: 45327.516 | Z24: 45327.672 | AE24: OK
A25: 10171563 | C25: 45329.625 | D25: - | E25: - | F25: TE02 | G25: TRF | H25: (RETORNO TE02) HNK SÃO JOSÉ-SC | I25: 05.254.957/0038-70 | J25: SÃO JOSÉ | K25: PONTA GROSSA | L25: TE02 SC | M25: A55650 | N25: 3145.2 | O25: =IFERROR(P25/N25,0) -> 0.57230065 | P25: 1800 | R25: 1267748 | S25: CARREGADO | T25: 4829638 | Y25: 45328.693 | Z25: 45329.294 | AE25: OK
A26: 10171564 | C26: 45327 | D26: - | E26: - | F26: TE02 | G26: TRF | H26: (RETORNO TE02) HNK SÃO JOSÉ-SC | I26: 50.221.019/0076-53 | J26: SÃO JOSÉ | K26: PONTA GROSSA | L26: TE02 SC | M26: A57390 | N26: 3145.2 | O26: =IFERROR(P26/N26,0) -> 0.57230065 | P26: 1800 | R26: 1267768 | S26: CARREGADO | T26: 4829764 | Y26: 45328.836 | Z26: 45328.89 | AE26: OK
A27: 10175824 | C27: 45329.417 | D27: 26 | E27: 32647 | F27: TE01 | G27: DTB | H27: SPAL JOINVILLE-SC | I27: 61.186.888/0175-92 | J27: PONTA GROSSA | K27: JOINVILLE | L27: SC | M27: A54730 | N27: 3157.14 | O27: =IFERROR(P27/N27,0) -> 0.76018168 | P27: 2400 | Q27: OK | R27: 1268842 | S27: CARREGADO | T27: 4836594 | U27: 0.41666667 | V27: 0.63541667 | W27: 0.21875 | X27: 08/02 08H | Y27: 45329.908 | Z27: 45330.253 | AE27: OK
A28: 10175897 | C28: 45329.458 | D28: 28 | E28: 34058 | F28: TE01 | G28: DTB | H28: LAGO AZUL REGENTE FEIJÓ-SP | I28: 58.844.424/0003-84 | J28: PONTA GROSSA | K28: REGENTE FEIJÓ | L28: SP INT. | M28: A55650 | N28: 5004.48 | O28: =IFERROR(P28/N28,0) -> 0.69937336 | P28: 3500 | Q28: OK | R28: 1268845 | S28: CARREGADO | T28: 4836610 | U28: 0.49583333 | V28: 0.625 | W28: 0.12916667 | X28: ORDEM | Y28: 45331.289 | Z28: 45331.431 | AE28: OK
A29: 10177845 | C29: 45328.708 | D29: 26 | E29: 31022 | F29: TE01 | G29: DTB | H29: CDA CURITIBA-PR | I29: 50.221.019/0083-82 | J29: PONTA GROSSA | K29: CURITIBA | L29: PR CAP. | M29: A56620 | N29: 2336.24 | O29: =IFERROR(P29/N29,0) -> 0.64205732 | P29: 1500 | Q29: OK | R29: 1268348 | S29: CARREGADO | T29: 4833087 | U29: 0.59652778 | V29: 0.81875 | W29: 0.22222222 | X29: ORDEM | Y29: 45330.436 | Z29: 45330.686 | AB29: OK | AC29: FALTA DE VASILHAME TE02 | AE29: OK
A30: 10177846 | C30: 45328.708 | D30: - | E30: - | F30: TE01 | G30: DTB | H30: (RETORNO TE02) CDA CURITIBA-PR | I30: 50.221.019/0083-82 | J30: CURITIBA | K30: PONTA GROSSA | L30: - | N30: 1446.19 | R30: - | S30: CANCELADA | T30: -
A31: 10178014 | C31: 45327 | D31: - | E31: - | F31: TE02 | G31: TRF | H31: (RETORNO TE02) HNK SÃO JOSÉ-SC | I31: 05.254.957/0038-70 | J31: SÃO JOSÉ | K31: PONTA GROSSA | L31: TE02 SC | M31: A55160 | N31: 3183 | O31: =IFERROR(P31/N31,0) -> 0.56550424 | P31: 1800 | R31: 1267587 | S31: CARREGADO | T31: 4828633 | Y31: 45329.023 | Z31: 45329.065 | AE31: OK
A32: 10178794 | C32: 45329.75 | D32: 26 | E32: 32647 | F32: TE01 | G32: DTB | H32: SPAL SÃO JOSÉ DO RIO PRETO-SP | I32: 61.186.888/0146-58 | J32: PONTA GROSSA | K32: SÃO JOSÉ DO RIO PRETO | L32: SP INT. | M32: A55160 | N32: 5991 | O32: =IFERROR(P32/N32,0) -> 0.75112669 | P32: 4500 | Q32: OK | R32: 1268851 | S32: CARREGADO | T32: 4836654 | U32: 0.45833333 | V32: 0.56944444 | W32: 0.11111111 | X32: 09/02 10H | Y32: 45331.36 | Z32: 45331.442 | AE32: OK
A33: 10179281 | C33: 45329.542 | D33: 26 | E33: 31922 | F33: TE01 | G33: TRF | H33: CDA ITU-SP | I33: 50.221.019/0047-19 | J33: PONTA GROSSA | K33: ITU | L33: SP | M33: A54920 | N33: 5174 | O33: =IFERROR(P33/N33,0) -> 0.77309625 | P33: 4000 | Q33: OK | R33: 1268490 | S33: CARREGADO | T33: 4834195 | U33: 0.14583333 | V33: 0.25 | W33: 0.10416667 | X33: ORDEM | Y33: 45330.303 | Z33: 45330.517 | AE33: OK
A34: 10179591 | C34: 45328.583 | D34: 26 | E34: 31922 | F34: TE01 | G34: TRF | H34: CDA CAÇAPAVA-SP | I34: 50.221.019/0084-63 | J34: PONTA GROSSA | K34: CAÇAPAVA | L34: SP | M34: A55660 | N34: 7880.37 | O34: =IFERROR(P34/N34,0) -> 0.69793677 | P34: 5500 | Q34: OK | R34: 1268453 | S34: CARREGADO | T34: 4833841 | U34: 0.63888889 | V34: 0.75 | W34: 0.11111111 | X34: ORDEM | Y34: 45330.847 | Z34: 45331.552 | AE34: OK
A35: 10179593 | C35: 45334.417 | D35: 26 | E35: 31922 | F35: TE01 | G35: TRF | H35: CDA CAÇAPAVA-SP | I35: 50.221.019/0084-63 | J35: PONTA GROSSA | K35: CAÇAPAVA | L35: SP | M35: A47130 | N35: 7880.37 | O35: =IFERROR(P35/N35,0) -> 0.69793677 | P35: 5500 | Q35: OK | R35: 1271867 | S35: CARREGADO | T35: 4851850 | U35: 0.74583333 | V35: 0.95208333 | X35: ORDEM | Y35: 45336.511 | Z35: 45336.678 | AE35: OK
A36: 10179594 | C36: 45334.417 | D36: 26 | E36: 31922 | F36: TE01 | G36: TRF | H36: CDA CAÇAPAVA-SP | I36: 50.221.019/0084-63 | J36: PONTA GROSSA | K36: CAÇAPAVA | L36: SP | M36: A56750 | N36: 7880.37 | O36: =IFERROR(P36/N36,0) -> 0.69793677 | P36: 5500 | Q36: OK | R36: 1271562 | S36: CARREGADO | T36: 4850447 | U36: 0.41805556 | V36: 0.61388889 | X36: ORDEM | Y36: 45335.725 | Z36: 45336.65 | AE36: OK
A37: 10181317 | C37: 45328.125 | D37: 26 | E37: 30740 | F37: TE02 | G37: TRF | H37: HNK SÃO JOSÉ-SC | I37: 50.221.019/0076-53 | J37: PONTA GROSSA | K37: SÃO JOSÉ | L37: SC | M37: A55640 | N37: 5053 | O37: =IFERROR(P37/N37,0) -> 0.59370671 | P37: 3000 | Q37: OK | R37: 1268471 | S37: CARREGADO | T37: 4834010 | U37: 0.69027778 | V37: 0.79166667 | W37: 0.10694444 | X37: ORDEM | Y37: 45329.622 | Z37: 45329.744 | AE37: OK
A38: 10181318 | C38: 45328.208 | D38: 26 | E38: 30740 | F38: TE02 | G38: TRF | H38: HNK SÃO JOSÉ-SC | I38: 50.221.019/0076-53 | J38: PONTA GROSSA | K38: SÃO JOSÉ | L38: SC | M38: A57130 | N38: 5053 | O38: =IFERROR(P38/N38,0) -> 0.59370671 | P38: 3000 | Q38: OK | R38: 1268567 | S38: CARREGADO | T38: 4834811 | U38: 0.61597222 | V38: 0.75 | W38: 0.19930556 | X38: ORDEM | Y38: 45330.333 | Z38: 45330.526 | AE38: OK
A39: 10185742 | C39: 45335.708 | D39: 28 | E39: 34058 | F39: TE01 | G39: DTB | H39: LAGO AZUL MARÍLIA-SP LUSITANA | I39: 58.844.424/0002-01 | J39: PONTA GROSSA | K39: MARÍLIA | L39: SP INT. | M39: A57860 | N39: 4325 | O39: =IFERROR(P39/N39,0) -> 0.69364162 | P39: 3000 | Q39: OK | R39: 1272225 | S39: CARREGADO | T39: 4852868 | U39: 0.52083333 | V39: 0.70694444 | X39: ORDEM | Y39: 45336.765 | Z39: 45336.777 | AE39: OK
A40: 10185743 | C40: 45335.708 | D40: 26 | E40: 30200 | F40: TE01 | G40: TRF | H40: CDA CURITIBA-PR | I40: 50.221.019/0083-82 | J40: PONTA GROSSA | K40: CURITIBA | L40: PR CAP. | M40: A54920 | N40: 2169.28 | O40: =IFERROR(P40/N40,0) -> 0.69147367 | P40: 1500 | Q40: OK | R40: 1272209 | S40: CARREGADO | T40: 4852798 | U40: 0.33333333 | V40: 0.55902778 | X40: ORDEM | Y40: 45336.244 | Z40: 45336.375 | AE40: OK
...

Sheet PEDÁGIO
A1: Nº Ocorrencia | B1: DT | C1: Frete | D1: ROTA | E1: COD. AGREGADO | F1: PLACA | G1: DATA EMBARQUE | H1: INICIO VIAGEM | I1: TERMINO VIAGEM | J1: VALOR ROTA A RECEBER | K1: STATUS VALIDAÇÃO HNK | L1: OBS | M1: Ação Ritmo
A2: 794826 | B2: 11111033 | C2: TE01 | D2: PONTA GROSSA X GUARULHOS | E2: A60950 | F2: AMP9049 | G2: 45689 | H2: 0.00069444444 | I2: 45444.597 | J2: R$ 219,00 | K2: FINALIZADA SEM DEV | L2: CUSTO SAP LANÇ | M2: Aguarda Demonst. Crédito
A3: 794828 | B3: 11111034 | C3: TE01 | D3: PONTA GROSSA X GUARULHOS | E3: A61060 | F3: ALC0D80 | G3: 45717 | H3: 0.3625 | I3: 45809.792 | J3: R$ 219,00 | K3: FINALIZADA SEM DEV | L3: CUSTO SAP LANÇ | M3: Aguarda Demonst. Crédito
A4: 794836 | B4: 11110447 | C4: TE01 | D4: PONTA GROSSA X GUARULHOS | E4: A60720 | F4: JZU1A40 | G4: 45717 | H4: 0.86666667 | I4: 45809.778 | J4: R$ 219,00 | K4: FINALIZADA SEM DEV | L4: CUSTO SAP LANÇ | M4: Aguarda Demonst. Crédito
A5: 782939 | B5: 11110908 | C5: TE01 | D5: PONTA GROSSA X GUARULHOS | E5: A63590 | F5: GHC4E75 | G5: 45717 | H5: 0.4625 | I5: 45809.323 | J5: 248,86 | K5: FINALIZADA SEM DEV | L5: CUSTO SAP LANÇ | M5: Aguarda Demonst. Crédito
A6: 812167 | B6: 11096082 | C6: TE01 | D6: PONTA GROSSA X GUARULHOS | E6: A62740 | F6: NJQ6C66 | G6: 45809 | H6: 0.31388889 | I6: 45870.573 | J6: 216.39 | K6: FINALIZADA SEM DEV | L6: CUSTO SAP LANÇ | M6: Aguarda Demonst. Crédito
A7: 812169 | B7: 11110446 | C7: TE01 | D7: PONTA GROSSA X GUARULHOS | E7: A62920 | F7: BCJ0C22 | G7: 45809 | H7: 0.89652778 | I7: 45839.924 | J7: 142.2 | K7: FINALIZADA SEM DEV | L7: CUSTO SAP LANÇ | M7: Aguarda Demonst. Crédito
A8: 794848 | B8: 11096081 | C8: TE02 | D8: PONTA GROSSA X GUARULHOS | E8: A61710 | F8: AZP0H53 | G8: 45809 | H8: 0.75 | I8: 45870.562 | J8: R$ 219,00 | K8: FINALIZADA SEM DEV | L8: RET. VAZIO | M8: Aguarda Demonst. Crédito
A9: 794854 | B9: 11106283 | C9: TE01 | D9: PONTA GROSSA X CURIITBA | E9: A63440 | F9: DPB1I84 | G9: 45809 | H9: 0.97847222 | I9: 45839.854 | J9: R$ 52,20 | K9: FINALIZADA SEM DEV | L9: CUSTO SAP LANÇ | M9: Aguarda Demonst. Crédito
A10: 794851 | B10: 11106284 | C10: TE01 | D10: PONTA GROSSA X CURIITBA | E10: A61130 | F10: ATJ1E14 | G10: 45809 | H10: 0.83819444 | I10: 45839.743 | J10: R$ 52,20 | K10: FINALIZADA SEM DEV | L10: CUSTO SAP LANÇ | M10: Aguarda Demonst. Crédito
A11: 794856 | B11: 11115111 | C11: TE01 | D11: PONTA GROSSA X GUARULHOS | E11: A62760 | F11: MPP1639 | G11: 45839 | H11: 0.71388889 | I11: 45870.747 | J11: R$ 219,00 | K11: FINALIZADA SEM DEV | L11: CUSTO SAP LANÇ | M11: Aguarda Demonst. Crédito
A12: 794859 | B12: 11115110 | C12: TE01 | D12: PONTA GROSSA X GUARULHOS | E12: A55640 | F12: RLI4I24 | G12: 45839 | H12: 45870.021 | I12: 45901.792 | J12: R$ 219,00 | K12: FINALIZADA SEM DEV | L12: CUSTO SAP LANÇ | M12: Aguarda Demonst. Crédito
A13: 812171 | B13: 11118603 | C13: TE01 | D13: PONTA GROSSA X GUARULHOS | E13: A63500 | F13: EFW3B74 | G13: 45870 | H13: 0.48574074 | I13: 45901.552 | J13: 166.8 | K13: FINALIZADA SEM DEV | L13: CUSTO SAP LANÇ | M13: Aguarda Demonst. Crédito
A14: 812173 | B14: 11118602 | C14: TE01 | D14: PONTA GROSSA X GUARULHOS | E14: A60790 | F14: DTE2491 | G14: 45870 | H14: 0.72898148 | I14: 45931.792 | J14: R$ 219,00 | K14: FINALIZADA SEM DEV | L14: CUSTO SAP LANÇ | M14: Aguarda Demonst. Crédito
A15: 785785 | B15: 11119430 | C15: TE02 | D15: PONTA GROSSA X GUARULHOS | E15: A63590 | F15: GHC4E75 | G15: 45870 | H15: 45901.077 | I15: 45931.073 | J15: R$ 219,00 | K15: FINALIZADA SEM DEV | L15: RET. VAZIO/ CUSTO SAP LANÇ | M15: Aguarda Demonst. Crédito
A16: 796463 | B16: 11121906 | C16: TE01 | D16: PONTA GROSSA X TIJUCAS | E16: A60560 | F16: ASP6I28 | G16: 45901 | H16: 0.57436343 | I16: 15/01/2025 10:00 | J16: R$ 177,00 | K16: FINALIZADA SEM DEV | L16: CUSTO SAP LANÇ | M16: Aguarda Demonst. Crédito
A17: 812176 | B17: 11118870 | C17: TE01 | D17: PONTA GROSSA X TIJUCAS | E17: A61130 | F17: ATJ1E14 | G17: 45901 | H17: 0.74967593 | I17: 15/01/2025 11:00 | J17: R$ 174.39 | K17: FINALIZADA SEM DEV | L17: CUSTO SAP LANÇ | M17: Aguarda Demonst. Crédito
A18: 812182 | B18: 11126308 | C18: TE01 | D18: PONTA GROSSA X GUARULHOS | E18: A62940 | F18: ETU2H73 | G18: 45901 | H18: 0.6362037 | I18: 13/01/2025 7:00 | J18: 257.72 | K18: FINALIZADA SEM DEV | L18: CUSTO SAP LANÇ | M18: Aguarda Demonst. Crédito
A19: 812184 | B19: 11122074 | C19: TE01 | D19: PONTA GROSSA X TIJUCAS | E19: A60720 | F19: JZU1A40 | G19: 45901 | H19: 0.86402778 | I19: 13/01/2025 10:20 | J19: 202.25 | K19: FINALIZADA SEM DEV | L19: CUSTO SAP LANÇ | M19: Aguarda Demonst. Crédito
A20: 788428 | B20: 11119431 | C20: TE01 | D20: PONTA GROSSA X GUARULHOS | E20: A61400 | F20: FUC4F49 | G20: 13/01/2025 | H20: 0.6056713 | I20: 15/01/2025 11:15 | J20: R$ 219,00 | K20: NÃO | L20: N TEM | M20: Finalizado
A21: 788433 | B21: 11119429 | C21: TE01 | D21: PONTA GROSSA X GUARULHOS | E21: A61710 | F21: AZP0H53 | G21: 13/01/2025 | H21: 0.84579861 | I21: 15/01/2025 11:15 | J21: R$ 219,00 | K21: NÃO | L21: HORARIOS NAO CONSTAM | M21: Finalizado
A22: 788443 | B22: 11126514 | C22: TE02 | D22: PONTA GROSSA X GUARULHOS | E22: A63610 | F22: AXN1D92 | G22: 13/01/2025 | H22: 0.2865625 | I22: 17/01/2025 02:10 | J22: R$ 219,00 | K22: NÃO | M22: Finalizado
A23: 800515 | B23: 11126513 | C23: TE02 | D23: GUARULHOS X PONTA GROSSA | E23: A63770 | F23: MLL6E83 | G23: 21/01/2025 | H23: 0 | I23: 23/01/2025 21:30 | J23: R$ 219,00 | K23: FINALIZADA SEM DEV | L23: CUSTO SAP LANÇ | M23: Aguarda Demonst. Crédito
A24: 795472 | B24: 11137473 | C24: TE01 | D24: PONTA GROSSA X SÃO PAULO | E24: A63640 | F24: AEW3F21 | G24: 15/01/2025 | H24: 15/01/2025 21:30 | I24: 18/01/2025 01:00 | J24: R$ 219,00 | K24: FINALIZADA SEM DEV | L24: CUSTO SAP LANÇ | M24: Aguarda Demonst. Crédito
A25: 795479 | B25: 11145471 | C25: TE01 | D25: PONTA GROSSA X OSASCO | E25: A60560 | F25: ASP6I28 | G25: 15/01/2025 | H25: 15/01/2025 23:20 | I25: 21/01/2025 20:40 | J25: R$ 219,00 | K25: FINALIZADA SEM DEV | L25: CUSTO SAP LANÇ | M25: Aguarda Demonst. Crédito
A26: 801383 | B26: 11150944 | C26: TE01 | D26: PONTA GROSSA X MOGI DAS CRUZES | E26: A63650 | F26: MEA5F57 | G26: 22/01/2025 | H26: 0.46527778 | I26: 23/01/2025 12:00 | J26: R$ 600.00 | K26: FINALIZADA SEM DEV | L26: CUSTO SAP LANÇ | M26: Aguarda Demonst. Crédito
A27: 801296 | B27: 11158161 | C27: TE02 | D27: PONTA GROSSA X GUARULHOS | E27: A63640 | F27: AEW3F21 | G27: 23/01/2025 | H27: 0.5 | I27: 27/01/2025 15:25 | J27: R$ 219,00 | K27: FINALIZADA SEM DEV | L27: RET. VAZIO/ CUSTO SAP LANÇ | M27: Aguarda Demonst. Crédito
A28: 816639 | B28: 11164287 | C28: TE01 | D28: PONTA GROSSA X OSASCO | E28: A61710 | F28: AZP0H53 | G28: 24/01/2025 | H28: 0.61805556 | I28: 27/01/2025 06:00 | J28: 216.39 | K28: FINALIZADA SEM DEV | L28: CUSTO SAP LANÇ | M28: Aguarda Demonst. Crédito
A29: 801393 | B29: 11166707 | C29: TE01 | D29: PONTA GROSSA X SÃO PAULO | E29: A63680 | F29: APN2H58 | G29: 25/01/2025 | H29: 0.78472222 | I29: 28/01/2025 16:10 | J29: R$ 219,00 | K29: FINALIZADA SEM DEV | L29: CUSTO SAP LANÇ | M29: Aguarda Demonst. Crédito
A30: 816632 | B30: 11161662 | C30: TE02 | D30: IGREJINHA X VESPASIANO CORREIA | E30: IOZ9E30 | F30: IOZ9E30 | G30: 30/01/2025 | H30: 0.60416667 | I30: 31/01/2025 11:25 | J30: R$ 143.00 | K30: FINALIZADA SEM DEV | L30: CUSTO SAP LANÇ | M30: Aguarda Demonst. Crédito
A31: 816647 | B31: 11161669 | C31: TE02 | D31: VESPASIANO CORREIA X IGREJINHA | E31: IOZ9E30 | F31: IOZ9E30 | G31: 31/01/2025 | H31: 0.47569444 | I31: 45718.41 | J31: R$ 60,50 | K31: FINALIZADA SEM DEV | L31: CUSTO SAP LANÇ | M31: Aguarda Demonst. Crédito
A32: 805114 | B32: 11172544 | C32: TE01 | D32: PONTA GROSSA X OSASCO | E32: A60720 | F32: JZU1A40 | G32: 29/01/2025 | H32: 0.72916667 | I32: 45659.042 | J32: R$ 219,00 | K32: FINALIZADA SEM DEV | L32: CUSTO SAP LANÇ | M32: Aguarda Demonst. Crédito
A33: 813902 | B33: 11180189 | C33: TE01 | D33: PONTA GROSSA X PORTO BELO | E33: A60560 | F33: ASP6I28 | G33: 29/01/2025 | H33: 0.77083333 | I33: 45659.167 | J33: 82.65 | K33: FINALIZADA SEM DEV | L33: CUSTO SAP LANÇ | M33: Aguarda Demonst. Crédito
B34: 11182101 | C34: TE02 | D34: IGREJINHA X JOAÇABA | E34: A58340 | F34: IEU5D15 | G34: 30/01/2025 | H34: 0.58333333 | I34: 31/01/2025 18:00 | K34: NÃO | M34: Finalizado
B35: 11182104 | C35: TE02 | D35: JOAÇABA X IGREJINHA | E35: A58340 | F35: IEU5D15 | G35: 45659 | H35: 0.41666667 | I35: 45718.396 | K35: NÃO | M35: Finalizado
B36: 11180188 | C36: TE01 | D36: PONTA GROSSA X PORTO BELO | E36: A63860 | F36: GBN9E05 | G36: 31/01/2025 | H36: 0.79166667 | I36: 45718.167 | J36: R$ 145,80 | K36: NÃO | M36: Finalizado
A37: 805126 | B37: 11182762 | C37: TE01 | D37: PONTA GROSSA X JUNDIAI | E37: A55640 | F37: RLI4I24 | G37: 31/01/2025 | H37: 0.20833333 | I37: 45718.292 | J37: R$ 496,80 | K37: FINALIZADA SEM DEV | L37: CUSTO SAP | M37: Aguarda Demonst. Crédito
B38: 11170686 | C38: TE01 | D38: PONTA GROSSA X GUARULHOS | E38: A63940 | F38: AYP3B37 | G38: 45718 | H38: 0 | I38: 45779.479 | K38: NAO | L38: VEICULO SEM TAG/ AUDINEI | M38: Finalizado
A39: 813915 | B39: 11186826 | C39: TE01 | D39: PONTA GROSSA X GUARULHOS | E39: A63820 | F39: ATF7H89 | G39: 45718 | H39: 0 | I39: 45749.917 | J39: 104.19 | K39: FINALIZADA SEM DEV | L39: CUSTO SAP | M39: Aguarda Demonst. Crédito
A40: 813919 | B40: 11185640 | C40: TE01 | D40: PONTA GROSSA X OSASCO | E40: A63320 | F40: MGF4H86 | G40: 45779 | H40: 0 | I40: 45840.542 | J40: 68.66 | K40: FINALIZADA SEM DEV | L40: CUSTO SAP | M40: Aguarda Demonst. Crédito
...

Sheet CONTROLE DE OCORRENCIAS
A1: DATA | B1: Tipo de Ocorrencia | C1: Nº Ocorrencia | D1: DT | E1: ROTA | F1: CTE | G1: ROMANEIO | H1: CÓD. AGREGADO | I1: PLACA | J1: VALOR A RECEBER (CLIENTE) | K1: CUSTO MOTORISTA | L1: STATUS VALIDAÇÃO HNK | M1: OBSERVAÇÃO | N1: Ação Ritmo
A2: 13/11/2024 | B2: DIÁRIA DE DESCARGA | C2: 742087 | D2: 10937188 | E2: PONTA GROSSA X SÃO PAULO | F2: 2018 | G2: 1455533 | H2: A61710 | I2: AZP0H53 | J2: - | K2: - | L2: FINALIZADA SEM DEV | M2: Não Gerou descarregou no dia | N2: Finalizado
A3: 14/11/2024 | B3: DIÁRIA DE DESCARGA | C3: 742803 | D3: 10939807 | E3: PONTA GROSSA X SÃO PAULO | F3: 2020 | G3: 1456766 | H3: A60560 | I3: ASP6I28 | J3: - | K3: - | L3: FINALIZADA SEM DEV | M3: Não Gerou descarregou no dia | N3: Finalizado
A4: 20/11/2024 | B4: DIÁRIA DE DESCARGA | C4: 746417 | D4: 10961709 | E4: PONTA GROSSA X CURITIBA | F4: 2021 | G4: 1462210 | H4: A61380 | I4: MIZ9F60 | J4: - | K4: - | L4: FINALIZADA SEM DEV | M4: Não Gerou descarregou no dia | N4: Finalizado
A5: 21/11/2024 | B5: FALTA DE VASILHAME | C5: 746772 | D5: 10961709 | E5: CURITIBA X PONTA GROSSA | G5: - | H5: A61380 | I5: MIZ9F60 | L5: FINALIZADA SEM DEV | M5: Finalizada aberta OC 762729, que foi validada | N5: Finalizado
A6: 21/11/2024 | B6: DIÁRIA DE DESCARGA | C6: 747307 | D6: 10961677 | E6: PONTA GROSSA X CURITIBA | F6: 2023 | G6: 1463425 | H6: A62780 | I6: ASO5I06 | J6: - | K6: - | L6: FINALIZADA SEM DEV | M6: aberto outra e validado OC 759955 | N6: Finalizado
A7: 22/11/2024 | B7: DIÁRIA DE DESCARGA | C7: 748039 | D7: 10961677 | E7: CURITIBA X PONTA GROSSA | G7: 1465435 | H7: A62780 | I7: ASO5I06 | J7: - | K7: - | L7: FINALIZADA SEM DEV | M7: Não Gerou descarregou no dia Fabrica P.Grossa | N7: Finalizado
A8: 22/11/2024 | B8: RET. VAZIO | C8: 748042 | D8: 10974234 | E8: PONTA GROSSA X JUNDIAI | F8: 2022 | G8: 1463577 | H8: A60720 | I8: JZU1A40 | J8: R$ 3.640,00 | L8: FINALIZADA SEM DEV | M8: Validado Gerado demonstrativo crédito | N8: Finalizado
A9: 25/11/2024 | B9: DIÁRIA DE DESCARGA | C9: 749553 | D9: 10974234 | E9: JUNDIAI X PONTA GROSSA | G9: - | H9: A60720 | I9: JZU1A40 | J9: R$ 1.600,00 | L9: FINALIZADA SEM DEV | M9: Validado Gerado demonstrativo crédito | N9: Finalizado
A10: 26/11/2024 | B10: DIÁRIA DE DESCARGA | C10: 750540 | D10: 10968119 | E10: GUARULHOS X PONTA GROSSA | F10: 497999 | G10: 1467712 | H10: A62620 | I10: AWG4F46 | L10: FINALIZADA SEM DEV | M10: Comprov. anexos, MOT. NÃO apres. quando chamado para descarga | N10: Finalizado
A11: 25/11/2024 | B11: FALTA DE AGENDA | C11: 749246 | D11: 10981833 | E11: PONTA GROSSA X CURITIBA | F11: 2024 | G11: 1465807 | H11: A61380 | I11: MIZ9F60 | J11: - | L11: FINALIZADA SEM DEV | M11: Não Gerou descarregou no dia | N11: Finalizado
A12: 25/11/2024 | B12: DIÁRIA DE DESCARGA | C12: 749650 | D12: 10987912 | E12: PONTA GROSSA X GUARULHOS | F12: 2026 | G12: 1466420 | H12: A62900 | I12: ACS4B05 | L12: FINALIZADA SEM DEV | M12: Não Gerou descarregou no dia | N12: Finalizado
A13: 25/11/2024 | B13: DIÁRIA DE DESCARGA | C13: 749653 | D13: 10987911 | E13: PONTA GROSSA X GUARULHOS | F13: 2028 | G13: 1466482 | H13: A62940 | I13: ETU2H73 | J13: - | K13: - | L13: CANCELADO | N13: Finalizado
A14: 27/11/2024 | B14: DIÁRIA DE DESCARGA | C14: 751940 | D14: 10974238 | E14: MARILIA X PONTA GROSSA | F14: 498075 | G14: 1468026 | H14: A62890 | I14: CVN3A01 | J14: - | K14: - | L14: CANCELADO | M14: CANCELADO POR CAMILA | N14: Finalizado
A15: 29/11/2024 | B15: PERDA DE AGENDA | C15: 753772 | D15: 10987836 | E15: PONTA GROSSA X CANDIDO MOTA | F15: 2032 | G15: 1470957 | H15: A62890 | I15: CVN3A01 | L15: FINALIZADA SEM DEV | M15: Fin. por Marcos, OC aberta antes chegada no cliente | N15: Finalizado
A16: 45334 | B16: PERDA DE AGENDA | C16: 755575 | D16: 10987836 | E16: PONTA GROSSA X CANDIDO MOTA | F16: 2032 | G16: 1470957 | H16: A62890 | I16: CVN3A01 | J16: R$ 3.200,00 | L16: FINALIZADA SEM DEV | M16: Validado HNK já recebido Demonstrativo de crédito | N16: Finalizado
A17: 45334 | B17: PERDA DE AGENDA | C17: 755372 | D17: 11004320 | E17: PONTA GROSSA X FOZ DO IGUAÇU | F17: 2035 | G17: 1472030 | H17: A62940 | I17: ETU2H73 | L17: FINALIZADA SEM DEV | M17: Descarregou no cliente - Não gerou diária descarga | N17: Finalizado
A18: 45363 | B18: TAXA DE DESCARGA | C18: 756598 | D18: 11004320 | E18: PONTA GROSSA X FOZ DO IGUAÇU | F18: 2035 | G18: 1472030 | H18: A62940 | I18: ETU2H73 | J18: R$ 208,00 | L18: FINALIZADA SEM DEV | M18: Validado HNK já recebido Demonstrativo de crédito | N18: Finalizado
A19: 45363 | B19: AVARIA | C19: 756953 | D19: 10989997 | E19: PONTA GROSSA X MARILIA | F19: 2030 | G19: 1469686 | H19: A63120 | I19: ALO5I04 | L19: FINALIZADA SEM DEV | M19: AG. VALIDAÇÃO DA ORIGEM P/ DIRECIONAR O DEBITO | N19: Finalizado
A20: 45363 | B20: DIARIA DE DESCARGA | C20: 757028 | D20: 11003631 | E20: ITAPETININGA X PONTA GROSSA | F20: 499427 | G20: 1474259 | H20: A63080 | I20: CUE4E05 | J20: R$ 800,00 | L20: FINALIZADA SEM DEV | M20: Validado HNK já recebido Demonstrativo de crédito | N20: Finalizado
A21: 45363 | B21: DIARIA DE DESCARGA | C21: 757265 | D21: 10989997 | E21: MARILIA X PONTA GROSSA | F21: 499425 | G21: 1474217 | H21: A63120 | I21: ALO5I04 | L21: CANCELADO | M21: CANCELADA PELA FÁBRICA | N21: Finalizado
A22: 45455 | B22: DIARIA DE DESCARGA | C22: 759955 | D22: 10961677 | E22: PONTA GROSSA X CURITIBA | F22: 2023 | G22: 1463425 | H22: A62780 | I22: ASO5I06 | J22: R$ 800,00 | K22: R$ 500.00 | L22: FINALIZADA SEM DEV | M22: Validado HNK já recebido Demonstrativo de crédito | N22: Finalizado
A23: 45485 | B23: TAXA DE DESCARGA | C23: 760765 | D23: 10987836 | E23: PONTA GROSSA X CANDIDO MOTA | F23: 2032 | G23: 1470957 | H23: A62890 | I23: CVN3A01 | J23: R$ 352,00 | L23: FINALIZADA SEM DEV | M23: Validado HNK já recebido Demonstrativo de crédito | N23: Finalizado
A24: 45485 | B24: DIARIA DE DESCARGA | C24: 760848 | D24: 11011017 | E24: MARILIA X PONTA GROSSA | F24: 277485 | G24: 1477828 | H24: A63080 | I24: CUE4E05 | L24: CANCELADO | M24: CANCELADO PELA FÁBRICA | N24: Finalizado
A25: 45485 | B25: DIARIA DE DESCARGA | C25: 760873 | D25: 11005911 | E25: GUARULHOS X PONTA GROSSA | F25: 500130 | G25: 1477476 | H25: A63120 | I25: ALO5I04 | L25: FINALIZADA SEM DEV | M25: Não Gerou descarregou no dia | N25: Finalizado
A26: 45485 | B26: DIARIA DE DESCARGA | C26: 761703 | D26: 11019253 | E26: PONTA GROSSA X CURITIBA | F26: 2044 | G26: 1478353 | H26: A62890 | I26: CVN3A01 | L26: FINALIZADA SEM DEV | M26: Não validaram a diária reaberto OC 768166 e Validado HNK | N26: Finalizado
A27: 45547 | B27: DIARIA DE DESCARGA | C27: 761929 | D27: 11011068 | E27: MARILIA X PONTA GROSSA | F27: 500185 | G27: 1477828 | H27: A63080 | I27: CUE4E05 | L27: FINALIZADA SEM DEV | M27: Mot. foi chamado, mas não compareceu, não podendo então validar a diária | N27: Finalizado
A28: 45577 | B28: AVARIA | C28: 761929 | D28: 10994934 | E28: PONTA GROSSA X PORTO VELHO | F28: 2033 | G28: 1471916 | H28: AYY5D91 | I28: AYY5D91 | L28: FINALIZADA SEM DEV | M28: AUTORIZADO VIA HNK DESCARTE E FINALIZADO OC. | N28: Finalizado
A29: 45577 | B29: AVARIA | C29: 762571 | D29: 10994936 | E29: PONTA GROSSA X PORTO VELHO | F29: 2034 | G29: 1471946 | H29: AYZ6C77 | I29: AYZ6C77 | L29: FINALIZADA SEM DEV | M29: AUTORIZADO VIA HNK DESCARTE E FINALIZADO OC. | N29: Finalizado
A30: 45577 | B30: DEV. ATIVOS - PALLET | C30: 762649 | D30: 11019253 | E30: PONTA GROSSA X CURITIBA | F30: 2044 | G30: 1478353 | H30: A62890 | I30: CVN3A01 | L30: FINALIZADA SEM DEV | M30: OC. aberta p/ fins de quitação saldo pois o canht. pallet nao foi assinado | N30: Finalizado
A31: 45577 | B31: FALTA DE VASILHAME | C31: 762729 | D31: 10961709 | E31: CURITIBA X PONTA GROSSA | F31: 2021 | G31: - | H31: A61380 | I31: MIZ9F60 | J31: R$ 1.601,60 | L31: FINALIZADA SEM DEV | M31: Validado HNK já recebido Demonstrativo de crédito | N31: Finalizado
A32: 45608 | B32: DIARIA DE DESCARGA | C32: 763113 | D32: 11025298 | E32: GUARULHOS X PONTA GROSSA | F32: 500456 | G32: 1479350 | H32: A60560 | I32: ASP6I28 | J32: R$ 800,00 | L32: FINALIZADA SEM DEV | M32: Validado HNK já recebido Demonstrativo de crédito | N32: Finalizado
A33: 45608 | B33: DIARIA DE DESCARGA | C33: 763122 | D33: 11019254 | E33: CURITIBA X PONTA GROSSA | F33: 183309 | G33: 1480233 | H33: A62890 | I33: CVN3A01 | J33: R$ 800,00 | L33: FINALIZADA SEM DEV | M33: Validado HNK já recebido Demonstrativo de crédito | N33: Finalizado
A34: 45638 | B34: DIARIA DE DESCARGA | C34: 764208 | D34: 11026961 | E34: GUARULHOS X PONTA GROSSA | F34: 500815 | G34: 1481106 | H34: A61710 | I34: AZP0H53 | J34: R$ 800,00 | L34: FINALIZADA SEM DEV | M34: Validado HNK já recebido Demonstrativo de crédito | N34: Finalizado
A35: 13/12/2024 | B35: TAXA DE DESCARGA | C35: 765522 | D35: 11030433 | E35: PONTA GROSSA X SÃO JOSÉ DOS PINHAIS | F35: 2047 | G35: 1482155 | H35: A61270 | I35: DBC8790 | J35: R$ 390,00 | L35: FINALIZADA SEM DEV | N35: Aguarda Demonst. Crédito
A36: 13/12/2024 | B36: DESCARTE PALLET | C36: 765576 | D36: 11030433 | E36: PONTA GROSSA X SÃO JOSÉ DOS PINHAIS | F36: 2047 | G36: 1482155 | H36: A61270 | I36: DBC8790 | L36: FINALIZADA SEM DEV | M36: Ocorrência incorreta - Finalizado HNK não anexado NF de pallets | N36: Finalizado
A37: 13/12/2024 | B37: AVARIA | C37: 765583 | D37: 11030433 | E37: PONTA GROSSA X SÃO JOSÉ DOS PINHAIS | F37: 2047 | G37: 1482155 | H37: A61270 | I37: DBC8790 | L37: FINALIZADA SEM DEV | M37: AUTORIZADO VIA HNK DESCARTE E FINALIZADO OC. | N37: Finalizado
A38: 16/12/2024 | B38: DESCARTE PALLET | C38: 766495 | D38: 11030433 | E38: PONTA GROSSA X SÃO JOSÉ DOS PINHAIS | F38: 2047 | G38: 1482155 | H38: A61270 | I38: DBC8790 | L38: FINALIZADA SEM DEV | M38: Ocorrência incorreta - Finalizado HNK - Anexado NF incorreta | N38: Finalizado
A39: 16/12/2024 | B39: DESCARTE PALLET | C39: 766825 | D39: 11030433 | E39: PONTA GROSSA X SÃO JOSÉ DOS PINHAIS | F39: 2047 | G39: 1482155 | H39: A61270 | I39: DBC8790 | L39: FINALIZADA SEM DEV | M39: BAIXADA PELA GEOVANA, MAS SEM TRAT. NA OC | N39: Finalizado
A40: 14/12/2024 | B40: DIARIA DE DESCARGA | C40: 766044 | D40: 11040247 | E40: PONTA GROSSA X GARULHOS | F40: 2049 | G40: 1482372 | H40: A60560 | I40: ASP6I28 | L40: CANCELADO | M40: Não Gerou | N40: Finalizado
...

Sheet RETIRADAS
A1: DT | B1: REMESSA | C1: DATA | D1: PL | E1: Peso | F1: Frete | G1: Canal | H1: Cliente | I1: CNPJ Destinatário | J1: Origem | K1: Cidade | L1: UF | M1: Frota | N1: Tarifa OTM | O1: Margem CF | P1: Valor CF | Q1: OC | R1: Romaneio | S1: Status | T1: Monitoramento (SM) | U1: DT/Hora Chegada Coleta | V1: Saída Coleta | W1: Tempo de Permanência | X1: Agenda Descarga | Y1: DT/ Hora Chegada no Cliente | Z1: Data/Hora Descarga | AA1: Tempo de Permanência | AB1: OC Galileu | AC1: Motivo | AD1: Valor | AE1: Baixa Galileu | AG1: MODALIDADE RETORNO | AH1: DESTINO | AI1: DATA/HORA CARREGAMENTO | AJ1: TEMPO DE ESPERA | AK1: FRETE DE RETORNO | AL1: KM ROTA | AM1: R$/KM
A2: 10921648 | C2: 45302 | D2: 26 | E2: 31.625 | F2: TE01 | G2: ASD | H2: CBD OSASCO - SP | I2: 47.508.411/0832-64 | J2: PONTA GROSSA | K2: OSASCO | L2: SP | M2: - | N2: 6500 | O2: =IFERROR(P2/N2,0) -> 0.65384615 | P2: 4250 | Q2: - | R2: - | S2: RETIRADA
A3: 10921637 | C3: 45302 | D3: 26 | E3: 31.625 | F3: TE01 | G3: ASD | H3: CBD OSASCO - SP | I3: 47.508.411/0832-64 | J3: PONTA GROSSA | K3: OSASCO | L3: SP | M3: - | N3: 6500 | O3: =IFERROR(P3/N3,0) -> 0.65384615 | P3: 4250 | Q3: - | R3: - | S3: RETIRADA
A4: 10914015 | C4: 45333 | D4: 26 | E4: 31.922 | F4: TE01 | G4: TRF | H4: CDA GUARULHOS-SP | I4: 50.221.019/0089-78 | J4: PONTA GROSSA | K4: GUARULHOS | L4: SP | M4: - | N4: 6200 | O4: =IFERROR(P4/N4,0) -> 0.80645161 | P4: 5000 | R4: - | S4: RETIRADA
A5: 10932681 | C5: 45454 | D5: 26 | E5: 31.922 | F5: TE01 | G5: TRF | H5: CDA GUARULHOS-SP | I5: 50.221.019/0089-78 | J5: PONTA GROSSA | K5: GUARULHOS | L5: SP | M5: - | N5: 6200 | O5: =IFERROR(P5/N5,0) -> 0.68548387 | P5: 4250 | Q5: - | R5: - | S5: RETIRADA
A6: 10932680 | C6: 45454 | D6: 26 | E6: 31.922 | F6: TE01 | G6: TRF | H6: CDA GUARULHOS-SP | I6: 50.221.019/0089-78 | J6: PONTA GROSSA | K6: GUARULHOS | L6: SP | M6: - | N6: 6200 | O6: =IFERROR(P6/N6,0) -> 0.68548387 | P6: 4250 | Q6: - | R6: - | S6: RETIRADA
A7: 10932679 | B7: 1001530134 | C7: 45484 | D7: 26 | E7: 31.922 | F7: TE01 | G7: TRF | H7: CDA GUARULHOS-SP | I7: 50.221.019/0089-78 | J7: PONTA GROSSA | K7: GUARULHOS | L7: SP | M7: - | N7: 6200 | O7: =IFERROR(P7/N7,0) -> 0.68548387 | P7: 4250 | Q7: - | R7: - | S7: RETIRADA
A8: 10928688 | B8: 1001527663 | C8: 45484 | D8: 26 | E8: 31.625 | F8: TE01 | G8: ASD | H8: ATACADAO S.A. PINHAIS-PR | I8: 75.315.333/0177-70 | J8: PONTA GROSSA | K8: PINHAIS | L8: PR OUT. | M8: - | N8: 2600 | O8: =IFERROR(P8/N8,0) -> 0.65384615 | P8: 1700 | Q8: - | R8: - | S8: RETIRADA
A9: 10932123 | B9: 1001529896 | C9: 45515 | D9: 26 | E9: 31.625 | F9: TE01 | G9: ASD | H9: ATACADAO S.A. PINHAIS-PR | I9: 75.315.333/0177-70 | J9: PONTA GROSSA | K9: PINHAIS | L9: PR OUT. | M9: - | N9: 2600 | O9: =IFERROR(P9/N9,0) -> 0.65384615 | P9: 1700 | Q9: - | R9: - | S9: RETIRADA
A10: 10937185 | C10: 45607 | D10: 26 | E10: 31.922 | F10: TE01 | G10: ASD | H10: CBD SÃO PAULO-SP | I10: 47.508.411/2627-89 | J10: PONTA GROSSA | K10: SÃO PAULO | L10: SP | M10: - | N10: 6700 | O10: =IFERROR(P10/N10,0) -> 0.67164179 | P10: 4500 | Q10: - | R10: - | S10: RETIRADA
A11: 10939809 | B11: 1001539018 | C11: 45637 | D11: 26 | E11: 31.922 | F11: TE01 | G11: ASD | H11: CBD SÃO PAULO-SP | I11: 47.508.411/2627-89 | J11: PONTA GROSSA | K11: SÃO PAULO | L11: SP | M11: - | N11: 6700 | O11: =IFERROR(P11/N11,0) -> 0.67164179 | P11: 4500 | Q11: - | R11: - | S11: DECLINADO
A12: 10944408 | B12: 1001543420 | C12: 13/11/2024 | D12: 26 | E12: 31.625 | F12: TE01 | G12: ASD | H12: ATACADAO S.A. PINHAIS-PR | I12: 75.315.333/0177-70 | J12: PONTA GROSSA | K12: PINHAIS | L12: PR OUT. | M12: - | N12: 2600 | O12: =IFERROR(P12/N12,0) -> 0 | P12: - | Q12: - | R12: - | S12: RETIRADA
A13: 10936279 | B13: 1001534062 | C13: 13/11/2024 | D13: 26 | E13: 31625 | F13: TE01 | G13: ASD | H13: CBD SÃO PAULO-SP | I13: 47.508.411/2627-89 | J13: PONTA GROSSA | K13: SÃO PAULO | L13: SP | M13: - | N13: 6700 | O13: =IFERROR(P13/N13,0) -> 0 | P13: - | Q13: - | R13: - | S13: RETIRADA | X13: 15/11/2024 06:00
A14: 10954666 | B14: 1001553098 | C14: 16/11/2024 | D14: 26 | E14: 33,43 | F14: TE01 | G14: ASD | H14: JAD ZOGNHEIB & CIA BAURU/SP | I14: 53.045.266/0001-17 | J14: PONTA GROSSA | K14: BAURU | L14: SP INT. | M14: - | N14: 5317 | O14: =IFERROR(P14/N14,0) -> 0 | P14: - | Q14: - | R14: - | S14: DECLINADO | X14: 19/11/2024 11:00
A15: 10957190 | B15: 1001555346 | C15: 16/11/2024 | D15: 26 | E15: 31.922 | F15: TE01 | G15: TRF | H15: CDA GUARULHOS-SP | I15: 50.221.019/0089-78 | J15: PONTA GROSSA | K15: GUARULHOS | L15: SP | M15: - | N15: 6200 | O15: =IFERROR(P15/N15,0) -> 0 | P15: - | Q15: - | R15: - | S15: DECLINADO
A16: 10959222 | B16: 1001558003 | C16: 16/11/2024 | D16: 26 | E16: 30847 | F16: TE02 | G16: DTB | H16: LAGO AZUL JUNDIAÍ-SP | I16: 58.844.424/0001-12 | J16: PONTA GROSSA | K16: JUNDIAÍ | L16: SP INT. | M16: - | N16: 5460 | O16: =IFERROR(P16/N16,0) -> 0 | P16: - | Q16: - | R16: - | S16: DECLINADO
A17: 10959223 | B17: 1001558001 | C17: 16/11/2024 | D17: - | E17: - | F17: TE02 | G17: DTB | H17: RETORNO TE02 LAGO AZUL JUNDIAÍ-SP | I17: 58.844.424/0001-12 | J17: JUNDIAÍ | K17: PONTA GROSSA | L17: TE02 | M17: - | N17: 4360 | O17: =IFERROR(P17/N17,0) -> 0 | P17: - | Q17: - | R17: - | S17: DECLINADO
A18: 10961708 | B18: 1001559552 | C18: 18/11/2024 | D18: 26 | E18: 31.625 | F18: TE01 | G18: TRF | H18: CDA GUARULHOS-SP | I18: 50.221.019/0089-78 | J18: PONTA GROSSA | K18: GUARULHOS | L18: SP | M18: - | N18: 6200 | O18: =IFERROR(P18/N18,0) -> 0 | P18: - | Q18: - | R18: - | S18: DECLINADO
A19: 10957533 | B19: 1001555680 | C19: 18/11/2024 | D19: 26 | E19: 31.922 | F19: TE01 | G19: TRF | H19: CDA GUARULHOS-SP | I19: 50.221.019/0089-78 | J19: PONTA GROSSA | K19: GUARULHOS | L19: SP | M19: - | N19: 6200 | O19: =IFERROR(P19/N19,0) -> 0 | P19: - | Q19: - | R19: - | S19: DECLINADO
A20: 10974235 | B20: 1001574088 | C20: 21/11/2024 | D20: 26 | E20: 29.747 | F20: TE02 | G20: DTB | H20: LAGO AZUL JUNDIAÍ-SP | I20: 58.844.424/0001-12 | J20: PONTA GROSSA | K20: JUNDIAÍ | L20: SP INT. | M20: CM Leonardo SP | N20: 5460 | O20: =IFERROR(P20/N20,0) -> 0 | S20: RETIRADA
A21: 10974240 | B21: 1001574091 | C21: 21/11/2024 | D21: - | E21: - | F21: TE02 | G21: DTB | H21: RETORNO TE02 LAGO AZUL JUNDIAÍ-SP | I21: 58.844.424/0001-12 | J21: JUNDIAÍ | K21: PONTA GROSSA | L21: TE02 | M21: CM Leonardo SP | N21: 4360 | O21: =IFERROR(P21/N21,0) -> 0 | S21: RETIRADA
A22: 10995377 | B22: 1001596036 | C22: 28/11/2024 | D22: 26 | E22: 31.526 | F22: TE02 | G22: TRF | H22: CDA CURITIBA-PR | I22: 50.221.019/0083-82 | J22: PONTA GROSSA | K22: CURITIBA | L22: PR | N22: 2402.4 | O22: =IFERROR(P22/N22,0) -> 0 | S22: RETIRADA
A23: 10995398 | B23: 1001596090 | C23: 28/11/2024 | D23: - | E23: - | F23: TE02 | G23: TRF | H23: (RETORNO TE02) CDA CURITIBA-PR | I23: 50.221.019/0083-82 | J23: CURITIBA | K23: PONTA GROSSA | L23: PR | N23: 1601.6 | O23: =IFERROR(P23/N23,0) -> 0 | S23: RETIRADA
A24: 10989507 | B24: 1001592302 | C24: 26/11/2024 | D24: 26 | E24: 33.139 | F24: TE01 | G24: ASD | H24: SUPERMERCADOS JAU SERVE LTDA JAÚ/SP | I24: 03.640.467/0011-66 | J24: PONTA GROSSA | K24: JAÚ | L24: SP INT. | M24: A61400 | N24: 5625 | O24: =IFERROR(P24/N24,0) -> 0 | Q24: OK | R24: 5427243 | S24: DECLINADO
A25: 10983846 | B25: 1001584894 | C25: 27/11/2024 | D25: 26 | E25: 31.489 | F25: TE01 | G25: ASD | H25: CASA AVENIDA COMERCIO E IMPORTAÇÃO CANDIDO MOTA SP | J25: PONTA GROSSA | K25: CANDIDO MOTA | L25: SP | N25: 5163 | O25: =IFERROR(P25/N25,0) -> 0 | S25: DECLINADO | X25: 28/11/2024 06:00
A26: 10994933 | B26: 1001596250 | C26: 27/11/2024 | D26: 22 | E26: 26.759 | F26: TE01 | G26: ASD | H26: ATACADÃO PORTO VELHO/RO | I26: 75.315.333/0213-78 | J26: PONTA GROSSA | K26: PORTO VELHO | L26: RO | N26: 29800 | O26: =IFERROR(P26/N26,0) -> 0 | S26: DECLINADO | X26: 45485.25
A27: 10989528 | B27: 1001592301 | C27: 28/11/2024 | D27: 26 | E27: 33.139 | F27: TE01 | G27: ASD | H27: SUPERMERCADOS JAU SERVE LTDA JAÚ/SP | I27: 03.640.467/0011-66 | J27: PONTA GROSSA | K27: JAÚ | L27: SP INT. | M27: A63080 | N27: 5625 | O27: =IFERROR(P27/N27,0) -> 0 | Q27: OK | R27: 1470837 | S27: DECLINADO | T27: 5941448
A28: 10994935 | B28: 1001596212 | C28: 29/11/2024 | D28: 26 | E28: 31.625 | F28: TE01 | G28: ASD | H28: ATACADÃO PORTO VELHO/RO | I28: 75.315.333/0213-78 | J28: PONTA GROSSA | K28: PORTO VELHO | L28: RO | N28: 29800 | O28: =IFERROR(P28/N28,0) -> 0 | S28: DECLINADO
A29: 10994146 | B29: 1001594356 | C29: 30/11/2024 | D29: 26 | E29: 30.961 | F29: TE01 | G29: ASD | H29: ATACADÃO SÃO PAULO/SP | I29: 75.315.333/0111-43 | J29: PONTA GROSSA | K29: SÃO PAULO | L29: SP | N29: 6700 | O29: =IFERROR(P29/N29,0) -> 0 | S29: DECLINADO
A30: 10997620 | B30: 1001598407 | C30: 45334 | D30: 26 | E30: 30.961 | F30: TE01 | G30: ASD | H30: ATACADÃO SÃO PAULO/SP | I30: 75.315.333/0111-43 | J30: PONTA GROSSA | K30: SÃO PAULO | L30: SP | N30: 6700 | O30: =IFERROR(P30/N30,0) -> 0 | S30: DECLINADO
A31: 11002562 | B31: 1001605210 | C31: 45334 | D31: 26 | E31: 31.625 | F31: TE01 | G31: TRF | H31: CDA GUARULHOS-SP | I31: 50.221.019/0089-78 | J31: PONTA GROSSA | K31: GUARULHOS | L31: SP | N31: 6200 | O31: =IFERROR(P31/N31,0) -> 0 | S31: DECLINADO
A32: 11025248 | B32: 1001624039 | C32: 45485 | D32: 26 | E32: 31.625 | F32: TE01 | G32: TRF | H32: CDA GUARULHOS-SP | I32: 50.221.019/0089-78 | J32: PONTA GROSSA | K32: GUARULHOS | L32: SP | N32: 6200 | O32: =IFERROR(P32/N32,0) -> 0 | S32: DECLINADO
A33: 11026795 | B33: 1001626393 | C33: 45547 | D33: 26 | E33: 31.922 | F33: TE01 | G33: TRF | H33: CDA GUARULHOS-SP | I33: 50.221.019/0089-78 | J33: PONTA GROSSA | K33: GUARULHOS | L33: SP | N33: 6200 | O33: =IFERROR(P33/N33,0) -> 0 | R33: 5435890 | S33: DECLINADO
A34: 11077710 | B34: 1001681482 | C34: 23/12/2024 | D34: 26 | E34: 32.597 | F34: TE01 | G34: DTB | H34: LAGO AZUL REGENTE FEIJÓ-SP | I34: 58.844.424/0003-84 | J34: PONTA GROSSA | K34: REGENTE FEIJÓ | L34: SP INT. | N34: 6161 | O34: 0 | S34: RETIRADA
A35: 11081506 | B35: 1001681769 | C35: 23/12/2024 | D35: 26 | E35: 33.431 | F35: TE01 | G35: DTB | H35: CDA CURITIBA-PR | I35: 50.221.019/0083-82 | J35: PONTA GROSSA | K35: CURITIBA | L35: PR | N35: 2696 | O35: =IFERROR(P35/N35,0) -> 0.15133531 | P35: 408 | Q35: OK | R35: 5444677 | S35: DECLINADO
A36: 11081521 | B36: 1001681808 | C36: 23/12/2024 | D36: 26 | E36: 33.431 | F36: TE01 | G36: DTB | H36: CDA CURITIBA-PR | I36: 50.221.019/0083-82 | J36: PONTA GROSSA | K36: CURITIBA | L36: PR | N36: 2696 | O36: =IFERROR(P36/N36,0) -> 0.15133531 | P36: 408 | Q36: OK | R36: 5444678 | S36: DECLINADO
A37: 11085535 | B37: 1001683670 | C37: 23/12/2024 | D37: 26 | E37: 32.504 | F37: TE01 | G37: ASD | H37: CASA AVENIDA COMERCIO E IMPORTAÇÃO CANDIDO MOTA SP | I37: 44.358.067/0037-89 | J37: PONTA GROSSA | K37: CANDIDO MOTA | L37: SP INT. | N37: 5317 | O37: =IFERROR(P37/N37,0) -> 0 | S37: DECLINADO
A38: 11113011 | B38: 1001708005 | C38: 45839 | D38: 26 | E38: 29.208 | F38: TE02 | G38: TRF | H38: CDA CURITIBA-PR | I38: 50.221.019/0083-82 | J38: PONTA GROSSA | K38: CURITIBA | L38: PR | M38: A61510 | N38: 2402.4 | O38: =IFERROR(P38/N38,0) -> 0 | S38: RETIRADA
A39: 11115252 | B39: 1001709813 | C39: 45536 | D39: 26 | E39: 30.02 | F39: TE02 | G39: TRF | H39: CDA GUARULHOS-SP | I39: 50.221.019/0089-78 | J39: PONTA GROSSA | K39: GUARULHOS | L39: SP | N39: 5460 | O39: =IFERROR(P39/N39,0) -> 0 | S39: RETIRADA
A40: 11115253 | B40: 1001709777 | C40: 45536 | D40: 3 | E40: 4.819 | F40: TE02 | G40: TRF | H40: RETORNO TE02 CDA GUARULHOS-SP | I40: 05.254.957/0028-06 | J40: GUARULHOS | K40: PONTA GROSSA | L40: PR OUT. | N40: 3640 | O40: =IFERROR(RETIRADAS!P39/RETIRADAS!N39,0) -> 0 | S40: RETIRADA
...

Sheet CUSTO EXTRA
A1: AGREGADO | B1: PLACA | C1: DÍG | D1: CLIENTE | E1: TIPO DE OCORRENCIA | F1: ROTA | G1: DATA | H1: CTE | I1: DT | J1: ROMANEIO | K1: Nº Ocorrencia | L1: VALOR A RECEBER (CLIENTE) | M1: VALOR A PAGAR (MOTORISTA) | N1: SENHA | O1: VALIDAÇÃO | P1: Status Ritmo
A2: AGREGADO | B2: AWC1157 | C2: 57 | D2: KEINEKEN | E2: DIARIA DESCARGA | F2: MARILIA X PONTA GROSSA | G2: 16/10/2024 | H2: 493534 | I2: 10865886 | J2: 1432759 | K2: 728084 | L2: R$ 800,00 | M2: R$ 500,00 | O2: APROVADO | P2: Pago
A3: AGREGADO | B3: AWC1157 | C3: 57 | D3: KEINEKEN | E3: DIARIA CARREGAMENTO | F3: PONTA GROSSA X PINHAIS | H3: - | I3: - | J3: - | M3: R$ 500,00 | P3: Pago
A4: AGREGADO | B4: MFI7B86 | C4: 86 | D4: HEINEKEN | E4: ESTADIA DESCARGA | F4: PONTA GROSSA X TIJUCAS SC | G4: 45302 | H4: 2010 | I4: 10917587 | J4: 1446846 | K4: 733273 | L4: R$ 800,00 | M4: R$ 500,00 | O4: APROVADO | P4: Pago
A5: AGREGADO | B5: ASO5I06 | C5: 6 | D5: HEINEKEN | E5: ESTADIA DESCARGA | F5: PONTA GROSSA X PINHAIS | G5: 21/11/2024 | H5: 2023 | I5: 10961677 | J5: 1463425 | K5: 759955 | L5: R$ 800,00 | M5: R$ 500,00 | O5: APROVADO | P5: Pago
A6: AGREGADO | B6: IEU5D15 | C6: 15 | D6: HEINEKEN | E6: ESTADIA DESCARGA | F6: JOAÇABA X IGREJINHA | G6: 45780 | H6: 43782 | I6: 11251333 | J6: 1540436 | K6: 828065 | L6: R$ 6.363,64 | M6: R$ 2.500.00 | O6: APROVADO | P6: Pago
A7: AGREGADO | B7: AXS2A52 | C7: 52 | D7: HEINEKEN | E7: ESTADIA DESCARGA | F7: GUARULHOS X PONTA GROSSA | G7: 45994 | H7: 512544 | I7: 11273314 | J7: 1544248 | K7: 832540 | L7: R$ 1818.18 | M7: R$ 1.000,00 | O7: APROVADO | P7: Pago
A8: AGREGADO | B8: MIS0H20 | C8: 20 | D8: HEINEKEN | E8: ESTADIA DESCARGA | F8: GUARULHOS X PONTA GROSSA | G8: 18/03/2025 | H8: 513706 | I8: 11277554 | J8: 1548665 | K8: 836622 | L8: R$ 800,00 | M8: R$ 500,00 | O8: APROVADO | P8: Pago
A9: AGREGADO | B9: BAP2G10 | C9: 10 | D9: HEINEKEN | E9: ESTADIA DESCARGA | F9: PONTA GROSSA X OSASCO | G9: 45994 | H9: 2172 | I9: 11265070 | J9: 1540397 | K9: 832415 | L9: R$ 3.636,36 | M9: R$ 1.000,00 | O9: APROVADO | P9: Não pagar
A10: AGREGADO | B10: BAP2G10 | C10: 10 | D10: HEINEKEN | E10: ESTADIA DESCARGA | F10: GUARULHOS X PONTA GROSSA | G10: 26/03/2025 | H10: 514707 | I10: 11300765 | J10: 1553352 | K10: 842290 | L10: R$ 1818.18 | M10: R$ 1.000,00 | O10: APROVADO | P10: Não pagar
A11: AGREGADO | B11: ATX0A70 | C11: 70 | D11: HEINEKEN | E11: ESTADIA DESCARGA | F11: GUARULHOS X PONTA GROSSA | G11: 45720 | H11: 516223 | I11: 11328138 | J11: 1560724 | K11: 850072 | L11: R$ 909,09 | M11: R$ 500,00 | O11: APROVADO | P11: Pago
A12: AGREGADO | B12: MGF4H86 | C12: 86 | D12: HEINEKEN | E12: ESTADIA DESCARGA | F12: PONTA GROSSA X OSASCO | G12: 45841 | H12: 2171 | I12: 11264930 | J12: 1540379 | K12: 829290 | M12: R$ 500,00 | O12: RECUSADA | P12: Pago
A13: AGREGADO | B13: AWD1B98 | C13: 98 | D13: HEINEKEN | E13: ESTADIA DESCARGA | F13: GUARULHOS X PONTA GROSSA | G13: 26/03/2025 | H13: 514820 | I13: 11325509 | J13: 1553802 | K13: 842686 | L13: R$ 800,00 | M13: R$ 500,00 | O13: APROVADO | P13: Pago
A14: AGREGADO | B14: AWD1B98 | C14: 98 | D14: HEINEKEN | E14: ESTADIA DESCARGA | F14: GUARULHOS X PONTA GROSSA | G14: 45720 | H14: 516270 | I14: 11328139 | J14: 1560932 | K14: 851230 | L14: R$2.727.27 | M14: R$ 1.500,00 | O14: APROVADO | P14: Pago
A15: AGREGADO | B15: MIS0H20 | C15: 20 | D15: HEINEKEN | E15: ESTADIA DESCARGA | F15: GUARULHOS X PONTA GROSSA | G15: 45812 | H15: 516540 | I15: 11339160 | J15: 1562285 | K15: 851363 | L15: R$ 1.818.18 | M15: R$ 1.000,00 | O15: APROVADO | P15: Pago
A16: AGREGADO | B16: MGF4H86 | C16: 86 | D16: HEINEKEN | E16: ESTADIA DESCARGA | F16: GUARULHOS X PONTA GROSSA | G16: 45812 | H16: 516482 | I16: 11339161 | J16: 1561927 | K16: 851367 | L16: R$ 1.818.18 | M16: R$ 1.820,00 | O16: APROVADO | P16: Pago
A17: AGREGADO | B17: ATX0A70 | C17: 70 | D17: HEINEKEN | E17: ESTADIA DESCARGA | F17: GUARULHOS X PONTA GROSSA | G17: 45965 | H17: 516670 | I17: 11344828 | J17: 1563051 | K17: 855000 | L17: R$2.727.27 | M17: R$ 1.000,00 | O17: APROVADO | P17: Pago
A18: AGREGADO | B18: AGG7742 | C18: 42 | D18: HEINEKEN | E18: ESTADIA DESCARGA | F18: PINHAIS X PONTA GROSSA | G18: 45719 | I18: 11256395 | K18: 825446 | L18: R$ 3.200,00 | M18: R$ 2.000.00 | O18: APROVADO | P18: Pago
A19: AGREGADO | B19: ATX0A70 | C19: 70 | D19: HEINEKEN | E19: ESTADIA DESCARGA | F19: GUARULHOS X PONTA GROSSA | G19: 45874 | H19: 520543 | I19: 11417243 | J19: 1586421 | K19: 872186 | L19: R$ 1.818.18 | M19: R$ 500,00 | O19: APROVADO | P19: Pago
A20: AGREGADO | B20: AXS2A52 | C20: 52 | D20: HEINEKEN | E20: ESTADIA DESCARGA | F20: GUARULHOS X PONTA GROSSA | G20: 45874 | H20: 520461 | I20: 11432484 | J20: 1586144 | K20: 872091 | L20: R$ 1.818.18 | M20: R$ 500,00 | O20: APROVADO | P20: Pago
A21: AGREGADO | B21: HZE2F70 | C21: 70 | D21: HEINEKEN | E21: TAXA DE DESCARGA | F21: IGREJINHA X ESTRELA | G21: 26/04/2025 | H21: 2226 | I21: 11392188 | J21: 1576116 | K21: 863945 | M21: R$ 450.00 | O21: PENDENTE | P21: Pago
A22: AGREGADO | B22: MIS0H20 | C22: 20 | D22: HEINEKEN | E22: ESTADIA DESCARGA | F22: ITU X PONTA GROSSA | G22: 16/05/2025 | H22: 522000 | I22: 11445917 | J22: 1593490 | K22: 877078 | L22: R$ 1.818.18 | M22: R$ 1.000,00 | O22: APROVADO | P22: Env. pgt
A23: AGREGADO | B23: AWD1B98 | C23: 98 | D23: HEINEKEN | E23: ESTADIA DESCARGA | F23: GUARULHOS X PONTA GROSSA | G23: 15/05/2025 | H23: 521648 | I23: 11441022 | J23: 1592119 | K23: 872186 | L23: R$ 1.818.18 | M23: R$ 1.000,00 | O23: APROVADO | P23: Env. pgt
A24: AGREGADO | B24: MEK4B39 | C24: 39 | D24: HEINEKEN | E24: ESTADIA DESCARGA | F24: ITU X PONTA GROSSA | G24: 16/05/2025 | H24: 521898 | I24: 11445909 | J24: 1593073 | K24: 876826 | L24: R$ 800,00 | M24: R$ 500,00 | O24: APROVADO | P24: Env. pgt
A25: AGREGADO | B25: ATX0A70 | C25: 70 | D25: HEINEKEN | E25: DIARIA DE DESCARGA | F25: GUARULHOS X PONTA GROSSA | G25: 14/04/2025 | H25: 516670 | I25: 11370424 | J25: 1569174 | K25: 858980 | L25: R$ 800.00 | O25: APROVADO GL
A26: AGREGADO | B26: MFY4I74 | C26: 74 | D26: HEINEKEN | E26: TAXA DE DESCARGA | F26: PONTA GROSSA X PINHAIS | G26: 16/04/2025 | H26: 2216 | I26: 11367914 | J26: 1568386 | K26: 858141 | L26: R$ 195.25 | O26: APROVADO
A27: AGREGADO | B27: MBP5D79 | C27: 79 | D27: HEINEKEN | E27: TAXA DE DESCARGA | F27: PONTA GROSSA X PALHOÇA | G27: 27/05/2025 | H27: 2252 | I27: 11455383 | J27: 1598295 | K27: 883868 | L27: R$ 144.00 | O27: APROVADO
A28: AGREGADO | B28: JLQ7H51 | C28: 51 | D28: HEINEKEN | E28: TAXA DE DESCARGA | F28: PONTA GROSSA X PALHOÇA | G28: 29/05/2025 | H28: 2247 | I28: 11450898 | J28: 1595703 | K28: 885447 | L28: R$ 156.00 | O28: APROVADO
A29: AGREGADO | B29: IPK4C72 | C29: 72 | D29: HEINEKEN | E29: DIARIA DE DESCARGA | F29: PONTA GROSSA X ITU | G29: 31/05/2025 | I29: 11483185 | J29: 1607107 | K29: 888933 | L29: 909.09 | M29: R$ 500,00 | O29: APROVADO | P29: Env. pgt
A30: AGREGADO | B30: HZE2F70 | C30: 70 | D30: HEINEKEN | E30: TAXA DE DESCARGA | F30: IGREJINHA X PELOTAS | G30: 45876 | H30: 2279 | I30: 11566124 | J30: 1633595 | K30: 907780 | L30: R$ 390.00 | M30: R$ 390.00 | O30: APROVADO | P30: Env. pgt
A31: AGREGADO | B31: MEK4B39 | C31: 39 | D31: HEINEKEN | E31: ESTADIA DESCARGA | F31: ITU X PONTA GROSSA | G31: 24/05/2025 | I31: 11459595 | J31: 1600671 | K31: 882034 | L31: 909.09 | M31: R$ 500,00 | O31: APROVADO | P31: Env. pgt
A32: AGREGADO | B32: ATQ3B32 | C32: 32 | D32: HEINEKEN | E32: ESTADIA DESCARGA | F32: GUARULHOS X PONTA GROSSA | G32: 20/08/2025 | H32: 523747 | I32: 11460143 | J32: 1602869 | K32: 884676 | L32: R$2.727,27 | M32: R$ 1.500.00 | O32: APROVADO | P32: Env. pgt
A33: AGREGADO | B33: AEW3F21 | C33: 21 | D33: HEINEKEN | E33: RETORNO VAZIO | F33: GUARULHOS X PONTA GROSSA | G33: 15/08/2025 | H33: 2288 | I33: 11665805 | J33: 1669523 | K33: 38270 | L33: R$ 4.429.55 | O33: APROVADO | P33: PAGO
A34: AGREGADO | B34: IUQ0B97 | C34: 97 | D34: HEINEKEN | E34: TAXA DE DESCARGA | F34: PONTA GROSSA X SJP | G34: 23/08/2025 | H34: 2294 | I34: 11680324 | J34: 1675410 | K34: 43546 | L34: R$ 325.00 | O34: APROVADO | P34: PAGO
A35: AGREGADO | B35: NJQ6C66 | C35: 66 | D35: HEINEKEN | E35: TAXA DE DESCARGA | F35: PONTA GROSSA X MARINGA | G35: 22/08/2025 | H35: 2290 | I35: 11684093 | J35: 1674761 | K35: 43093 | L35: R$ 52.00 | O35: APROVADO | P35: PAGO
A36: AGREGADO | B36: MFY4I74 | C36: 74 | D36: HEINEKEN | E36: ESTADIA DESCARGA | F36: PONTA GROSSA X CAMBE | G36: 45665 | H36: 2284 | I36: 11631881 | J36: 1657830 | K36: 25634 | L36: R$ 4.800.00 | M36: R$ 2.500.00 | O36: APROVADO | P36: Env. pgt
A37: AGREGADO | B37: ATI8J32 | C37: 32 | D37: HEINEKEN | E37: ESTADIA DESCARGA | F37: PONTA GROSSA X CAMBE | G37: 45665 | H37: 2283 | I37: 11631962 | J37: 1657832 | K37: 25552 | L37: R$ 4.800.00 | M37: R$ 2.500.00 | O37: APROVADO | P37: Env. pgt
A38: AGREGADO | B38: AWD1B98 | C38: 98 | D38: HEINEKEN | E38: TAXA DE DESCARGA | F38: PONTA GROSSA X ITU | G38: 23/08/2025 | H38: 2292 | I38: 11689753 | J38: 1675193 | K38: 46561 | L38: R$ 1.337.73 | O38: APROVADO | P38: PAGO

Sheet MONIT. HNK
B1: AGREGADO | C1: PLACA CAVALO | D1: PLACA DA CARRETA | E1: MOTORISTA | F1: LOCALIZAÇÃO | G1: UF | H1: ORIGEM | I1: UF | J1: CIDADE DESTINO | K1: UF | L1: VEÍCULO ESTÁ? CARREGADO/VAZIO | M1: STATUS | N1: OBSERVAÇÃO
A2: 1 | B2: A63800 | C2: MFY4I74 | D2: ASF9J60 | E2: CLAUDINEI | F2: MARINGA | G2: PR | H2: MARINGA | I2: PR | J2: CURITIBA | K2: PR | L2: PROGRAMADO | M2: PROGRAMADO
A3: 2 | B3: A64030 | C3: MEK4B39 | D3: ATR6534 | E3: JOAO | F3: CURITIBA | G3: PR | L3: INDISPONÍVEL | M3: DESAGREGAÇÃO
A4: 4 | B4: A64570 | C4: AWD1B98 | D4: AUR6B22 | E4: EMERSON | F4: SÃO JOSÉ DOS PINHAIS | G4: PR | L4: VAZIO PR/SC/RS | M4: DISPONÍVEL
A5: 5 | B5: A64410 | C5: MIS0H20 | D5: AWO2238 | F5: BLUMENAU | G5: SC | L5: INDISPONÍVEL | M5: MANUTENÇÃO CAVALO
A6: 6 | B6: A66420 | C6: IUQ0B97 | D6: BAA1452 | E6: LAURO | F6: MARINGA | G6: PR | H6: MARINGA | I6: PR | J6: CURITIBA | K6: PR | L6: PROGRAMADO | M6: PROGRAMADO
A7: 7 | B7: A66530 | C7: ANE6H54 | D7: AUR6B01 | E7: PATRICK | F7: PONTA GROSSA | G7: PR | L7: VAZIO PR/SC/RS | M7: DESAGREGAÇÃO
A8: 8 | B8: A66490 | C8: ATI8J32 | D8: BBK8794 | E8: SERGIO | F8: CURITIBA | G8: PR | H8: CURITIBA | I8: PR | J8: MARINGA | K8: PR | L8: PROGRAMADO | M8: EM TRÂNSITO | N8: TROCA DE OPERAÇÃO
A9: 9 | B9: A66590 | C9: ATD4J25 | D9: SET7F10 | E9: PATRICIA | F9: PONTA GROSSA | G9: PR | L9: INDISPONÍVEL | M9: PROGRAMADO TERCEIRO
A10: 10 | B10: A66620 | C10: TAS0H43 | D10: APF2J30 | E10: MATHEUS | F10: PONTA GROSSA | G10: PR | L10: INDISPONÍVEL | M10: PROBLEMAS PESSOAIS

Sheet AGREGADOS SPOT
A1: FROTA | B1: CAVALO | C1: CODIGO SR | D1: CARRETA | E1: MEDIDA | F1: TAG | G1: MOTORISTA | H1: CPF | I1: TELEFONE | J1: STATUS | K1: TECNOLOGIA
A2: A18000 | B2: BAT2820 | C2: C7315 | D2: AZV7123 | G2: HAMILTON DE LIMA | H2: 614.498.579-49 | I2: 41996428568 | J2: DESAGREGOU
A3: A55160 | B3: ILI8C72 | C3: C7143 | D3: AWO2238 | F3: SEM PARAR | G3: JULIANO DE LIMA SCHRAMM | H3: 780.037.840-34 | I3: 51981351912 | J3: DESAGREGOU
A4: A56540 | B4: AOO8H10 | C4: LC1937 | D4: ENG0375 | F4: TAGGY repom | G4: AUGUSTO CESAR DA ROSA | H4: 301.899.738-70 | I4: 11992946939 | J4: DESAGREGOU
A5: A58340 | B5: IEU5D15 | C5: C7314 | D5: AZV0533 | F5: SEM PARAR | G5: FERNANDO PEDRAO FORTES | H5: 000.417.630-84 | I5: 51981461938 | J5: DESAGREGOU
A6: A60000 | B6: EPB9B81 | C6: LC1907 | D6: EAU9974 | F6: TAGGY repom | G6: DAVID SAVARIS BARROS (ASA DELTA) | H6: 087.190.329-60 | I6: 4196879190 | J6: DESAGREGOU
A7: A60290 | B7: AVV0D80 | C7: C7153 | D7: AWO2852 | F7: TAGGY repom | G7: LUIZ CARLOS DA SILVA | H7: 774.763.609-15 | I7: 44991589147 | J7: DESAGREGOU
A8: A63410 | B8: NUF0C80 | C8: LC1936 | D8: EOA0241 | F8: TAGGY repom | G8: JHONATAN FELIPE DE OLIVEIRA CASSOL | H8: 087.607.979-67 | I8: 4191724120 | J8: DESAGREGOU
A9: A62500 | B9: IZX7E98 | C9: C7316 | D9: BAA1371 | G9: DAVID FELIPE SOARES | H9: 118.858.229-10 | I9: 41998668303 | J9: DESAGREGOU
A10: A63320 | B10: MGF4H86 | C10: RT1741 | D10: BBK8796 | F10: SEM PARAR | G10: MIGUEL DE OLIVEIRA | H10: 000.583.139-31 | I10: 95984064310 | J10: DESAGREGOU | K10: AUTOTRAC
A11: A63650 | B11: MEA5F57 | C11: C1230 | D11: ATR6829 | F11: SEM PARAR | G11: RICARDO DE OLIVEIRA | H11: 263.057.568-30 | I11: 44998001018 | J11: DESAGREGOU
A12: A63800 | B12: MFY4I74 | C12: C7356 | D12: ASF9J60 | F12: SEM PARAR | G12: CLAUDINEI GONÇALVES MATTOS | H12: 986.852.529-20 | I12: 41996333287 | J12: ATIVO
A13: A63820 | B13: ATF7H89 | C13: C921 | D13: APH0J19 | F13: TAGGY repom | G13: GUELBER PIRES COSTA | H13: 690.220.032-72 | I13: 65996318724 | J13: DESAGREGOU
A14: A63850 | B14: BAN2A60 | C14: RT1612 | D14: AUR6B01 | F14: SEM PARAR | G14: CLAUDIO DE SOUZA SANTOS | H14: 687.750.839-49 | I14: 41999408564 | J14: DESAGREGOU
A15: A63860 | B15: GBN9E05 | C15: RT1619 | D15: AUR6B22 | F15: SEM PARAR | G15: ANTONIO LOPES RIBEIRO | H15: 765.717.265-72 | I15: 11933483975 | J15: DESAGREGOU
A16: A63880 | B16: FPU4H61 | C16: LC2014 | D16: QXY6B68 | F16: TAGGY repom | G16: FABIO CORREA GOIVINHO | H16: 072.287.259-30 | I16: 44997130480 | J16: DESAGREGOU
A17: A63910 | B17: AYZ5B53 | C17: C7131 | D17: AWI3960 | F17: SEM PARAR | J17: DESAGREGOU
A18: A63940 | B18: AYP3B37 | C18: C910 | D18: APF2943 | G18: AUDINEI NATALINO VICENTE | H18: 953.675.009-00 | I18: 41997757508 / 41999775084 | J18: DESAGREGOU
A19: A63930 | B19: BCY5G45 | C19: C2306 | D19: SET7F10 | G19: ZULMAR WERLICE | H19: 946.942.069-15 | I19: 48999099089 | J19: DESAGREGOU
